Workbook

Sheet Customers
A1: customer_id | B1: customer_name | C1: city | D1: signup_date
A2: 1 | B2: Aarav Shah | C2: Mumbai | D2: 45748
A3: 2 | B3: Diya Patel | C3: Ahmedabad | D3: 3/23/2025
A4: 3 | B4: Rohan Mehta | C4: Pune | D4: 12/24/2025
A5: 4 | B5: Ananya Joshi | C5: Bengaluru | D5: 45785
A6: 5 | B6: Vivaan Desai | C6: Bengaluru | D6: 6/24/2025
A7: 6 | B7: Isha Shah | C7: Delhi | D7: 5/23/2025
A8: 7 | B8: Aditya Patel | C8: Mumbai | D8: 3/21/2025
A9: 8 | B9: Meera Mehta | C9: Mumbai | D9: 4/21/2025
A10: 9 | B10: Arjun Desai | C10: Jaipur | D10: 6/22/2025
A11: 10 | B11: Kiara Joshi | C11: Ahmedabad | D11: 2/22/2025
A12: 11 | B12: Kabir Shah | C12: Ahmedabad | D12: 2/17/2025
A13: 12 | B13: Riya Patel | C13: Mumbai | D13: 7/14/2025
A14: 13 | B14: Dev Mehta | C14: Bengaluru | D14: 2/19/2025
A15: 14 | B15: Sara Desai | C15: Bengaluru | D15: 45723
A16: 15 | B16: Neil Joshi | C16: Ahmedabad | D16: 6/26/2025
A17: 16 | B17: Tara Shah | C17: Bengaluru | D17: 45819
A18: 17 | B18: Yash Patel | C18: Jaipur | D18: 5/16/2025
A19: 18 | B19: Nisha Mehta | C19: Bengaluru | D19: 1/23/2025
A20: 19 | B20: Raj Desai | C20: Surat | D20: 8/24/2025
A21: 20 | B21: Aanya Joshi | C21: Pune | D21: 45698

Sheet Orders
A1: order_id | B1: customer_id | C1: product_id | D1: order_date | E1: quantity | F1: Product Price | G1: Revenu | H1: Category | I1: month number | J1: Category2
A2: 1001 | B2: 4 | C2: 113 | D2: 45698 | E2: 3 | F2: =_xlfn.XLOOKUP(C2,Products!A:A,Products!D:D) -> 2200 | G2: =Table3[[#This Row],[quantity]]*Table3[[#This Row],[Product Price]] -> 6600 | H2: =_xlfn.XLOOKUP(C2,Products!A:A,Products!C:C) -> Accessories | I2: =MONTH(D2) -> 2 | J2: =_xlfn.XLOOKUP(C2,Products!A:A,Products!B:B) -> Backpack
A3: 1002 | B3: 20 | C3: 112 | D3: 45953 | E3: 2 | F3: =_xlfn.XLOOKUP(C3,Products!A:A,Products!D:D) -> 1800 | G3: =Table3[[#This Row],[quantity]]*Table3[[#This Row],[Product Price]] -> 3600 | H3: =_xlfn.XLOOKUP(C3,Products!A:A,Products!C:C) -> Furniture | I3: =MONTH(D3) -> 10 | J3: =_xlfn.XLOOKUP(C3,Products!A:A,Products!B:B) -> Table Lamp
A4: 1003 | B4: 3 | C4: 102 | D4: 45996 | E4: 2 | F4: =_xlfn.XLOOKUP(C4,Products!A:A,Products!D:D) -> 1200 | G4: =Table3[[#This Row],[quantity]]*Table3[[#This Row],[Product Price]] -> 2400 | H4: =_xlfn.XLOOKUP(C4,Products!A:A,Products!C:C) -> Electronics | I4: =MONTH(D4) -> 12 | J4: =_xlfn.XLOOKUP(C4,Products!A:A,Products!B:B) -> Wireless Mouse
A5: 1004 | B5: 10 | C5: 103 | D5: 45777 | E5: 1 | F5: =_xlfn.XLOOKUP(C5,Products!A:A,Products!D:D) -> 3500 | G5: =Table3[[#This Row],[quantity]]*Table3[[#This Row],[Product Price]] -> 3500 | H5: =_xlfn.XLOOKUP(C5,Products!A:A,Products!C:C) -> Electronics | I5: =MONTH(D5) -> 4 | J5: =_xlfn.XLOOKUP(C5,Products!A:A,Products!B:B) -> Mechanical Keyboard
A6: 1005 | B6: 13 | C6: 109 | D6: 45890 | E6: 3 | F6: =_xlfn.XLOOKUP(C6,Products!A:A,Products!D:D) -> 12000 | G6: =Table3[[#This Row],[quantity]]*Table3[[#This Row],[Product Price]] -> 36000 | H6: =_xlfn.XLOOKUP(C6,Products!A:A,Products!C:C) -> Furniture | I6: =MONTH(D6) -> 8 | J6: =_xlfn.XLOOKUP(C6,Products!A:A,Products!B:B) -> Office Chair
A7: 1006 | B7: 6 | C7: 112 | D7: 45839 | E7: 2 | F7: =_xlfn.XLOOKUP(C7,Products!A:A,Products!D:D) -> 1800 | G7: =Table3[[#This Row],[quantity]]*Table3[[#This Row],[Product Price]] -> 3600 | H7: =_xlfn.XLOOKUP(C7,Products!A:A,Products!C:C) -> Furniture | I7: =MONTH(D7) -> 7 | J7: =_xlfn.XLOOKUP(C7,Products!A:A,Products!B:B) -> Table Lamp
A8: 1007 | B8: 9 | C8: 123 | D8: 46007 | E8: 1 | F8: =_xlfn.XLOOKUP(C8,Products!A:A,Products!D:D) -> 5500 | G8: =Table3[[#This Row],[quantity]]*Table3[[#This Row],[Product Price]] -> 5500 | H8: =_xlfn.XLOOKUP(C8,Products!A:A,Products!C:C) -> Home Appliances | I8: =MONTH(D8) -> 12 | J8: =_xlfn.XLOOKUP(C8,Products!A:A,Products!B:B) -> Coffee Maker
A9: 1008 | B9: 20 | C9: 121 | D9: 45745 | E9: 2 | F9: =_xlfn.XLOOKUP(C9,Products!A:A,Products!D:D) -> 1800 | G9: =Table3[[#This Row],[quantity]]*Table3[[#This Row],[Product Price]] -> 3600 | H9: =_xlfn.XLOOKUP(C9,Products!A:A,Products!C:C) -> Clothing | I9: =MONTH(D9) -> 3 | J9: =_xlfn.XLOOKUP(C9,Products!A:A,Products!B:B) -> Hoodie
A10: 1009 | B10: 6 | C10: 115 | D10: 45852 | E10: 3 | F10: =_xlfn.XLOOKUP(C10,Products!A:A,Products!D:D) -> 1500 | G10: =Table3[[#This Row],[quantity]]*Table3[[#This Row],[Product Price]] -> 4500 | H10: =_xlfn.XLOOKUP(C10,Products!A:A,Products!C:C) -> Accessories | I10: =MONTH(D10) -> 7 | J10: =_xlfn.XLOOKUP(C10,Products!A:A,Products!B:B) -> Wallet
A11: 1010 | B11: 18 | C11: 108 | D11: 46008 | E11: 3 | F11: =_xlfn.XLOOKUP(C11,Products!A:A,Products!D:D) -> 1800 | G11: =Table3[[#This Row],[quantity]]*Table3[[#This Row],[Product Price]] -> 5400 | H11: =_xlfn.XLOOKUP(C11,Products!A:A,Products!C:C) -> Electronics | I11: =MONTH(D11) -> 12 | J11: =_xlfn.XLOOKUP(C11,Products!A:A,Products!B:B) -> Power Bank
A12: 1011 | B12: 2 | C12: 108 | D12: 45674 | E12: 3 | F12: =_xlfn.XLOOKUP(C12,Products!A:A,Products!D:D) -> 1800 | G12: =Table3[[#This Row],[quantity]]*Table3[[#This Row],[Product Price]] -> 5400 | H12: =_xlfn.XLOOKUP(C12,Products!A:A,Products!C:C) -> Electronics | I12: =MONTH(D12) -> 1 | J12: =_xlfn.XLOOKUP(C12,Products!A:A,Products!B:B) -> Power Bank
A13: 1012 | B13: 13 | C13: 109 | D13: 45691 | E13: 2 | F13: =_xlfn.XLOOKUP(C13,Products!A:A,Products!D:D) -> 12000 | G13: =Table3[[#This Row],[quantity]]*Table3[[#This Row],[Product Price]] -> 24000 | H13: =_xlfn.XLOOKUP(C13,Products!A:A,Products!C:C) -> Furniture | I13: =MONTH(D13) -> 2 | J13: =_xlfn.XLOOKUP(C13,Products!A:A,Products!B:B) -> Office Chair
... A151: 1150 | B151: 13 | C151: 111 | D151: 45766 | E151: 4 | F151: =_xlfn.XLOOKUP(C151,Products!A:A,Products!D:D) -> 7000 | G151: =Table3[[#This Row],[quantity]]*Table3[[#This Row],[Product Price]] -> 28000 | H151: =_xlfn.XLOOKUP(C151,Products!A:A,Products!C:C) -> Furniture | I151: =MONTH(D151) -> 4 | J151: =_xlfn.XLOOKUP(C151,Products!A:A,Products!B:B) -> Bookshelf
G152: =SUM(Table3[Revenu]) -> 1965300

Sheet Products
A1: product_id | B1: product_name | C1: category | D1: price | E1: Total revenue
A2: 101 | B2: Laptop Pro 14 | C2: Electronics | D2: 65000 | E2: =SUMIF(Orders!C:C,A2,Orders!G:G) -> 780000
A3: 109 | B3: Office Chair | C3: Furniture | D3: 12000 | E3: =SUMIF(Orders!C:C,A3,Orders!G:G) -> 204000
A4: 124 | B4: Air Fryer | C4: Home Appliances | D4: 6200 | E4: =SUMIF(Orders!C:C,A4,Orders!G:G) -> 93000
A5: 118 | B5: Dumbbells | C5: Sports | D5: 2500 | E5: =SUMIF(Orders!C:C,A5,Orders!G:G) -> 72500
A6: 110 | B6: Study Desk | C6: Furniture | D6: 9500 | E6: =SUMIF(Orders!C:C,A6,Orders!G:G) -> 66500
A7: 123 | B7: Coffee Maker | C7: Home Appliances | D7: 5500 | E7: =SUMIF(Orders!C:C,A7,Orders!G:G) -> 66000
A8: 105 | B8: Bluetooth Headphones | C8: Electronics | D8: 4500 | E8: =SUMIF(Orders!C:C,A8,Orders!G:G) -> 63000
A9: 114 | B9: Travel Bag | C9: Accessories | D9: 3200 | E9: =SUMIF(Orders!C:C,A9,Orders!G:G) -> 57600
A10: 103 | B10: Mechanical Keyboard | C10: Electronics | D10: 3500 | E10: =SUMIF(Orders!C:C,A10,Orders!G:G) -> 56000
A11: 111 | B11: Bookshelf | C11: Furniture | D11: 7000 | E11: =SUMIF(Orders!C:C,A11,Orders!G:G) -> 56000
A12: 106 | B12: Smart Watch | C12: Electronics | D12: 7500 | E12: =SUMIF(Orders!C:C,A12,Orders!G:G) -> 52500
A13: 113 | B13: Backpack | C13: Accessories | D13: 2200 | E13: =SUMIF(Orders!C:C,A13,Orders!G:G) -> 48400
... A26: 119 | B26: T-Shirt | C26: Clothing | D26: 900 | E26: =SUMIF(Orders!C:C,A26,Orders!G:G) -> 3600

Sheet Analysis
A1: Q1 — Total Revenue
A3: ₹1,965,300
A5: Q2 — Revenue by Category
A7: Category | B7: Sum of Revenu
A8: Accessories | B8: 131500
A9: Clothing | B9: 85100
A10: Electronics | B10: 1067700
A11: Furniture | B11: 358900
A12: Home Appliances | B12: 186000
A13: Sports | B13: 136100
A14: Grand Total | B14: 1965300
A16: Q3 — Monthly Revenue
A18: Month | B18: Sum of Revenu
A19: 1 | B19: 90100
A20: 2 | B20: 136500
A21: 3 | B21: 194100
A22: 4 | B22: 81700
A23: 5 | B23: 233900
A24: 6 | B24: 320900
A25: 7 | B25: 271000
A26: 8 | B26: 123600
A27: 9 | B27: 204200
A28: 10 | B28: 80200
A29: 11 | B29: 62900
A30: 12 | B30: 166200
A31: Grand Total | B31: 1965300
A33: Q4 — Top 10 Products by Revenue
A35: product_id | B35: product_name | C35: category | D35: price | E35: Total revenue
A36: 101 | B36: Laptop Pro 14 | C36: Electronics | D36: 65000 | E36: =SUMIF(Orders!C:C,A36,Orders!G:G) -> 780000
A37: 109 | B37: Office Chair | C37: Furniture | D37: 12000 | E37: =SUMIF(Orders!C:C,A37,Orders!G:G) -> 204000
A38: 124 | B38: Air Fryer | C38: Home Appliances | D38: 6200 | E38: =SUMIF(Orders!C:C,A38,Orders!G:G) -> 93000
A39: 118 | B39: Dumbbells | C39: Sports | D39: 2500 | E39: =SUMIF(Orders!C:C,A39,Orders!G:G) -> 72500
A40: 110 | B40: Study Desk | C40: Furniture | D40: 9500 | E40: =SUMIF(Orders!C:C,A40,Orders!G:G) -> 66500
A41: 123 | B41: Coffee Maker | C41: Home Appliances | D41: 5500 | E41: =SUMIF(Orders!C:C,A41,Orders!G:G) -> 66000
A42: 105 | B42: Bluetooth Headphones | C42: Electronics | D42: 4500 | E42: =SUMIF(Orders!C:C,A42,Orders!G:G) -> 63000
A43: 114 | B43: Travel Bag | C43: Accessories | D43: 3200 | E43: =SUMIF(Orders!C:C,A43,Orders!G:G) -> 57600
A44: 103 | B44: Mechanical Keyboard | C44: Electronics | D44: 3500 | E44: =SUMIF(Orders!C:C,A44,Orders!G:G) -> 56000
A45: 111 | B45: Bookshelf | C45: Furniture | D45: 7000 | E45: =SUMIF(Orders!C:C,A45,Orders!G:G) -> 56000
A47: Q5 — Top 10 Customers by Revenue
A49: customer_id | B49: Sum of Revenu | C49: Customer name | D49: Revenu
...

Sheet Dashboard
D1: E-Commerce Sales Analysis Dashboard
A2: Total Revenue | C2: Total Orders | E2: Average Order Value | G2: Total Products
A3: 1965300 | C3: 150 | E3: 13102 | G3: 25
A4: Monthly Revenue | E4: Revenue by Category
A18: Top 10 Products by Revenue | E18: Top 10 Customers by Revenue
A34: Monthly Order Volume

Sheet Revenu by Category
A3: Category | B3: Sum of Revenu
A4: Accessories | B4: 131500
A5: Clothing | B5: 85100
A6: Electronics | B6: 1067700
A7: Furniture | B7: 358900
A8: Home Appliances | B8: 186000
A9: Sports | B9: 136100
A10: Grand Total | B10: 1965300

Sheet Top 10 Customers by Revenue
A3: customer_id | B3: Sum of Revenu | C3: Customer name
A4: 16 | B4: 413500 | C4: =_xlfn.XLOOKUP(A4,Customers!A:A,Customers!B:B) -> Tara Shah
A5: 18 | B5: 244700 | C5: =_xlfn.XLOOKUP(A5,Customers!A:A,Customers!B:B) -> Nisha Mehta
A6: 15 | B6: 238600 | C6: =_xlfn.XLOOKUP(A6,Customers!A:A,Customers!B:B) -> Neil Joshi
A7: 13 | B7: 172900 | C7: =_xlfn.XLOOKUP(A7,Customers!A:A,Customers!B:B) -> Dev Mehta
A8: 14 | B8: 158900 | C8: =_xlfn.XLOOKUP(A8,Customers!A:A,Customers!B:B) -> Sara Desai
A9: 8 | B9: 99500 | C9: =_xlfn.XLOOKUP(A9,Customers!A:A,Customers!B:B) -> Meera Mehta
A10: 12 | B10: 87000 | C10: =_xlfn.XLOOKUP(A10,Customers!A:A,Customers!B:B) -> Riya Patel
A11: 5 | B11: 70900 | C11: =_xlfn.XLOOKUP(A11,Customers!A:A,Customers!B:B) -> Vivaan Desai
A12: 6 | B12: 62400 | C12: =_xlfn.XLOOKUP(A12,Customers!A:A,Customers!B:B) -> Isha Shah
A13: 9 | B13: 56600 | C13: =_xlfn.XLOOKUP(A13,Customers!A:A,Customers!B:B) -> Arjun Desai
A14: Grand Total | B14: 1605000

Sheet Top 10 Products
A1: product_id | B1: product_name | C1: category | D1: price | E1: Total revenue
A2: 101 | B2: Laptop Pro 14 | C2: Electronics | D2: 65000 | E2: =SUMIF(Orders!C:C,A2,Orders!G:G) -> 780000
A3: 109 | B3: Office Chair | C3: Furniture | D3: 12000 | E3: =SUMIF(Orders!C:C,A3,Orders!G:G) -> 204000
A4: 124 | B4: Air Fryer | C4: Home Appliances | D4: 6200 | E4: =SUMIF(Orders!C:C,A4,Orders!G:G) -> 93000
A5: 118 | B5: Dumbbells | C5: Sports | D5: 2500 | E5: =SUMIF(Orders!C:C,A5,Orders!G:G) -> 72500
A6: 110 | B6: Study Desk | C6: Furniture | D6: 9500 | E6: =SUMIF(Orders!C:C,A6,Orders!G:G) -> 66500
A7: 123 | B7: Coffee Maker | C7: Home Appliances | D7: 5500 | E7: =SUMIF(Orders!C:C,A7,Orders!G:G) -> 66000
A8: 105 | B8: Bluetooth Headphones | C8: Electronics | D8: 4500 | E8: =SUMIF(Orders!C:C,A8,Orders!G:G) -> 63000
A9: 114 | B9: Travel Bag | C9: Accessories | D9: 3200 | E9: =SUMIF(Orders!C:C,A9,Orders!G:G) -> 57600
A10: 103 | B10: Mechanical Keyboard | C10: Electronics | D10: 3500 | E10: =SUMIF(Orders!C:C,A10,Orders!G:G) -> 56000
A11: 111 | B11: Bookshelf | C11: Furniture | D11: 7000 | E11: =SUMIF(Orders!C:C,A11,Orders!G:G) -> 56000

Sheet Revenue Above ₹100000
A3: customer_id | B3: Sum of Revenu | C3: Customer Name
A4: 13 | B4: 172900 | C4: =_xlfn.XLOOKUP(A4,Customers!A:A,Customers!B:B) -> Dev Mehta
A5: 14 | B5: 158900 | C5: =_xlfn.XLOOKUP(A5,Customers!A:A,Customers!B:B) -> Sara Desai
A6: 15 | B6: 238600 | C6: =_xlfn.XLOOKUP(A6,Customers!A:A,Customers!B:B) -> Neil Joshi
A7: 16 | B7: 413500 | C7: =_xlfn.XLOOKUP(A7,Customers!A:A,Customers!B:B) -> Tara Shah
A8: 18 | B8: 244700 | C8: =_xlfn.XLOOKUP(A8,Customers!A:A,Customers!B:B) -> Nisha Mehta
A9: Grand Total | B9: 1228600

Sheet Revenue by Customer
A3: customer_id | B3: Sum of Revenu | C3: Customer Name
A4: 1 | B4: 12100 | C4: Aarav Shah
A5: 2 | B5: 54300 | C5: Diya Patel
A6: 3 | B6: 28700 | C6: Rohan Mehta
A7: 4 | B7: 48800 | C7: Ananya Joshi
A8: 5 | B8: 70900 | C8: Vivaan Desai
A9: 6 | B9: 62400 | C9: Isha Shah
A10: 7 | B10: 18500 | C10: Aditya Patel
A11: 8 | B11: 99500 | C11: Meera Mehta
A12: 9 | B12: 56600 | C12: Arjun Desai
A13: 10 | B13: 35500 | C13: Kiara Joshi
A14: 11 | B14: 28400 | C14: Kabir Shah
A15: 12 | B15: 87000 | C15: Riya Patel
... A23: 20 | B23: 47200 | C23: Aanya Joshi
A24: Grand Total | B24: 1965300

Sheet Top 10  Quantity Sold
A3: product_id | B3: Sum of quantity | C3: Product Name
A4: 118 | B4: 29 | C4: =_xlfn.XLOOKUP(A4,Products!A:A,Products!B:B) -> Dumbbells
A5: 108 | B5: 23 | C5: =_xlfn.XLOOKUP(A5,Products!A:A,Products!B:B) -> Power Bank
A6: 113 | B6: 22 | C6: =_xlfn.XLOOKUP(A6,Products!A:A,Products!B:B) -> Backpack
A7: 107 | B7: 20 | C7: =_xlfn.XLOOKUP(A7,Products!A:A,Products!B:B) -> Phone Stand
A8: 102 | B8: 18 | C8: =_xlfn.XLOOKUP(A8,Products!A:A,Products!B:B) -> Wireless Mouse
A9: 112 | B9: 18 | C9: =_xlfn.XLOOKUP(A9,Products!A:A,Products!B:B) -> Table Lamp
A10: 114 | B10: 18 | C10: =_xlfn.XLOOKUP(A10,Products!A:A,Products!B:B) -> Travel Bag
A11: 120 | B11: 17 | C11: =_xlfn.XLOOKUP(A11,Products!A:A,Products!B:B) -> Jeans
A12: 109 | B12: 17 | C12: =_xlfn.XLOOKUP(A12,Products!A:A,Products!B:B) -> Office Chair
A13: 115 | B13: 17 | C13: =_xlfn.XLOOKUP(A13,Products!A:A,Products!B:B) -> Wallet
A14: 117 | B14: 17 | C14: =_xlfn.XLOOKUP(A14,Products!A:A,Products!B:B) -> Yoga Mat
A15: Grand Total | B15: 216

Sheet Revenu by Month
A3: Month | B3: Sum of Revenu
A4: 1 | B4: 90100
A5: 2 | B5: 136500
A6: 3 | B6: 194100
A7: 4 | B7: 81700
A8: 5 | B8: 233900
A9: 6 | B9: 320900
A10: 7 | B10: 271000
A11: 8 | B11: 123600
A12: 9 | B12: 204200
A13: 10 | B13: 80200
A14: 11 | B14: 62900
A15: 12 | B15: 166200
A16: Grand Total | B16: 1965300

Sheet Orders by Month
A3: Months | B3: Count of order_id
A4: 1 | B4: 12
A5: 2 | B5: 10
A6: 3 | B6: 20
A7: 4 | B7: 9
A8: 5 | B8: 13
A9: 6 | B9: 14
A10: 7 | B10: 9
A11: 8 | B11: 14
A12: 9 | B12: 11
A13: 10 | B13: 12
A14: 11 | B14: 8
A15: 12 | B15: 18
A16: Grand Total | B16: 150

Sheet Monthly Average Order Value 
A3: Months | B3: Sum of Revenu | C3: Order Count | D3: AOV
A4: 1 | B4: 90100 | C4: 12 | D4: =B4/C4 -> 7508.3333
A5: 2 | B5: 136500 | C5: 10 | D5: =B5/C5 -> 13650
A6: 3 | B6: 194100 | C6: 20 | D6: =B6/C6 -> 9705
A7: 4 | B7: 81700 | C7: 9 | D7: =B7/C7 -> 9077.7778
A8: 5 | B8: 233900 | C8: 13 | D8: =B8/C8 -> 17992.308
A9: 6 | B9: 320900 | C9: 14 | D9: =B9/C9 -> 22921.429
A10: 7 | B10: 271000 | C10: 9 | D10: =B10/C10 -> 30111.111
A11: 8 | B11: 123600 | C11: 14 | D11: =B11/C11 -> 8828.5714
A12: 9 | B12: 204200 | C12: 11 | D12: =B12/C12 -> 18563.636
A13: 10 | B13: 80200 | C13: 12 | D13: =B13/C13 -> 6683.3333
A14: 11 | B14: 62900 | C14: 8 | D14: =B14/C14 -> 7862.5
A15: 12 | B15: 166200 | C15: 18 | D15: =B15/C15 -> 9233.3333
A16: Grand Total | B16: 1965300 | C16: 150 | D16: =B16/C16 -> 13102
